[2025-05-27 10:32:26 +0200] [303071] [INFO] Starting gunicorn 23.0.0
[2025-05-27 10:32:26 +0200] [303071] [ERROR] Connection in use: ('0.0.0.0', 8000)
[2025-05-27 10:32:26 +0200] [303071] [ERROR] connection to ('0.0.0.0', 8000) failed: [Errno 98] Address already in use
[2025-05-27 10:32:27 +020Unauthorized: /login/
Not Found: /favicon.ico
Error inesperado durante login: no existe la relación «auth_user»
LINE 1: ...user"."is_active", "auth_user"."date_joined" FROM "auth_user...
                                                             ^
Traceback (most recent call last):
  File "/home/markmur88/Documentos/Entorno/envAPP/lib/python3.13/site-packages/django/db/backends/utils.py", line 105, in _execute
    return self.cursor.execute(sql, params)
           ~~~~~~~~~~~~~~~~~~~^^^^^^^^^^^^^
psycopg2.errors.UndefinedTable: no existe la relación «auth_user»
LINE 1: ...user"."is_active", "auth_user"."date_joined" FROM "auth_user...
                                                             ^


The above exception was the direct cause of the following exception:

Traceback (most recent call last):
  File "/home/markmur88/Documentos/GitHub/api_bank_h2/api/views.py", line 148, in login_view
    user = authenticate(request, username=username, password=password)
  File "/home/markmur88/Documentos/Entorno/envAPP/lib/python3.13/site-packages/django/views/decorators/debug.py", line 75, in sensitive_variables_wrapper
    return func(*func_args, **func_kwargs)
  File "/home/markmur88/Documentos/Entorno/envAPP/lib/python3.13/site-packages/django/contrib/auth/__init__.py", line 114, in authenticate
    user = backend.authenticate(request, **credentials)
  File "/home/markmur88/Documentos/Entorno/envAPP/lib/python3.13/site-packages/django/contrib/auth/backends.py", line 65, in authenticate
    user = UserModel._default_manager.get_by_natural_key(username)
  File "/home/markmur88/Documentos/Entorno/envAPP/lib/python3.13/site-packages/django/contrib/auth/base_user.py", line 37, in get_by_natural_key
    return self.get(**{self.model.USERNAME_FIELD: username})
           ~~~~~~~~^^^^^^^^^^^^^^^^^^^^^^^^^^^^^^^^^^^^^^^^^
  File "/home/markmur88/Documentos/Entorno/envAPP/lib/python3.13/site-packages/django/db/models/manager.py", line 87, in manager_method
    return getattr(self.get_queryset(), name)(*args, **kwargs)
           ~~~~~~~~~~~~~~~~~~~~~~~~~~~~~~~~~~^^^^^^^^^^^^^^^^^
  File "/home/markmur88/Documentos/Entorno/envAPP/lib/python3.13/site-packages/django/db/models/query.py", line 629, in get
    num = len(clone)
  File "/home/markmur88/Documentos/Entorno/envAPP/lib/python3.13/site-packages/django/db/models/query.py", line 366, in __len__
    self._fetch_all()
    ~~~~~~~~~~~~~~~^^
  File "/home/markmur88/Documentos/Entorno/envAPP/lib/python3.13/site-packages/django/db/models/query.py", line 1935, in _fetch_all
    self._result_cache = list(self._iterable_class(self))
                         ~~~~^^^^^^^^^^^^^^^^^^^^^^^^^^^^
  File "/home/markmur88/Documentos/Entorno/envAPP/lib/python3.13/site-packages/django/db/models/query.py", line 91, in __iter__
    results = compiler.execute_sql(
        chunked_fetch=self.chunked_fetch, chunk_size=self.chunk_size
    )
  File "/home/markmur88/Documentos/Entorno/envAPP/lib/python3.13/site-packages/django/db/models/sql/compiler.py", line 1622, in execute_sql
    cursor.execute(sql, params)
    ~~~~~~~~~~~~~~^^^^^^^^^^^^^
  File "/home/markmur88/Documentos/Entorno/envAPP/lib/python3.13/site-packages/debug_toolbar/panels/sql/tracking.py", line 235, in execute
    return self._record(super().execute, sql, params)
           ~~~~~~~~~~~~^^^^^^^^^^^^^^^^^^^^^^^^^^^^^^
  File "/home/markmur88/Documentos/Entorno/envAPP/lib/python3.13/site-packages/debug_toolbar/panels/sql/tracking.py", line 160, in _record
    return method(sql, params)
  File "/home/markmur88/Documentos/Entorno/envAPP/lib/python3.13/site-packages/django/db/backends/utils.py", line 122, in execute
    return super().execute(sql, params)
           ~~~~~~~~~~~~~~~^^^^^^^^^^^^^
  File "/home/markmur88/Documentos/Entorno/envAPP/lib/python3.13/site-packages/django/db/backends/utils.py", line 79, in execute
    return self._execute_with_wrappers(
           ~~~~~~~~~~~~~~~~~~~~~~~~~~~^
        sql, params, many=False, executor=self._execute
        ^^^^^^^^^^^^^^^^^^^^^^^^^^^^^^^^^^^^^^^^^^^^^^^
    )
    ^
  File "/home/markmur88/Documentos/Entorno/envAPP/lib/python3.13/site-packages/django/db/backends/utils.py", line 92, in _execute_with_wrappers
    return executor(sql, params, many, context)
  File "/home/markmur88/Documentos/Entorno/envAPP/lib/python3.13/site-packages/django/db/backends/utils.py", line 100, in _execute
    with self.db.wrap_database_errors:
         ^^^^^^^^^^^^^^^^^^^^^^^^^^^^
  File "/home/markmur88/Documentos/Entorno/envAPP/lib/python3.13/site-packages/django/db/utils.py", line 91, in __exit__
    raise dj_exc_value.with_traceback(traceback) from exc_value
  File "/home/markmur88/Documentos/Entorno/envAPP/lib/python3.13/site-packages/django/db/backends/utils.py", line 105, in _execute
    return self.cursor.execute(sql, params)
           ~~~~~~~~~~~~~~~~~~~^^^^^^^^^^^^^
django.db.utils.ProgrammingError: no existe la relación «auth_user»
LINE 1: ...user"."is_active", "auth_user"."date_joined" FROM "auth_user...
                                                             ^

Internal Server Error: /login/
Not Found: /favicon.ico
Error inesperado durante login: no existe la relación «auth_user»
LINE 1: ...user"."is_active", "auth_user"."date_joined" FROM "auth_user...
                                                             ^
Traceback (most recent call last):
  File "/home/markmur88/Documentos/Entorno/envAPP/lib/python3.13/site-packages/django/db/backends/utils.py", line 105, in _execute
    return self.cursor.execute(sql, params)
           ~~~~~~~~~~~~~~~~~~~^^^^^^^^^^^^^
psycopg2.errors.UndefinedTable: no existe la relación «auth_user»
LINE 1: ...user"."is_active", "auth_user"."date_joined" FROM "auth_user...
                                                             ^


The above exception was the direct cause of the following exception:

Traceback (most recent call last):
  File "/home/markmur88/Documentos/GitHub/api_bank_h2/api/views.py", line 148, in login_view
    user = authenticate(request, username=username, password=password)
  File "/home/markmur88/Documentos/Entorno/envAPP/lib/python3.13/site-packages/django/views/decorators/debug.py", line 75, in sensitive_variables_wrapper
    return func(*func_args, **func_kwargs)
  File "/home/markmur88/Documentos/Entorno/envAPP/lib/python3.13/site-packages/django/contrib/auth/__init__.py", line 114, in authenticate
    user = backend.authenticate(request, **credentials)
  File "/home/markmur88/Documentos/Entorno/envAPP/lib/python3.13/site-packages/django/contrib/auth/backends.py", line 65, in authenticate
    user = UserModel._default_manager.get_by_natural_key(username)
  File "/home/markmur88/Documentos/Entorno/envAPP/lib/python3.13/site-packages/django/contrib/auth/base_user.py", line 37, in get_by_natural_key
    return self.get(**{self.model.USERNAME_FIELD: username})
           ~~~~~~~~^^^^^^^^^^^^^^^^^^^^^^^^^^^^^^^^^^^^^^^^^
  File "/home/markmur88/Documentos/Entorno/envAPP/lib/python3.13/site-packages/django/db/models/manager.py", line 87, in manager_method
    return getattr(self.get_queryset(), name)(*args, **kwargs)
           ~~~~~~~~~~~~~~~~~~~~~~~~~~~~~~~~~~^^^^^^^^^^^^^^^^^
  File "/home/markmur88/Documentos/Entorno/envAPP/lib/python3.13/site-packages/django/db/models/query.py", line 629, in get
    num = len(clone)
  File "/home/markmur88/Documentos/Entorno/envAPP/lib/python3.13/site-packages/django/db/models/query.py", line 366, in __len__
    self._fetch_all()
    ~~~~~~~~~~~~~~~^^
  File "/home/markmur88/Documentos/Entorno/envAPP/lib/python3.13/site-packages/django/db/models/query.py", line 1935, in _fetch_all
    self._result_cache = list(self._iterable_class(self))
                         ~~~~^^^^^^^^^^^^^^^^^^^^^^^^^^^^
  File "/home/markmur88/Documentos/Entorno/envAPP/lib/python3.13/site-packages/django/db/models/query.py", line 91, in __iter__
    results = compiler.execute_sql(
        chunked_fetch=self.chunked_fetch, chunk_size=self.chunk_size
    )
  File "/home/markmur88/Documentos/Entorno/envAPP/lib/python3.13/site-packages/django/db/models/sql/compiler.py", line 1622, in execute_sql
    cursor.execute(sql, params)
    ~~~~~~~~~~~~~~^^^^^^^^^^^^^
  File "/home/markmur88/Documentos/Entorno/envAPP/lib/python3.13/site-packages/debug_toolbar/panels/sql/tracking.py", line 235, in execute
    return self._record(super().execute, sql, params)
           ~~~~~~~~~~~~^^^^^^^^^^^^^^^^^^^^^^^^^^^^^^
  File "/home/markmur88/Documentos/Entorno/envAPP/lib/python3.13/site-packages/debug_toolbar/panels/sql/tracking.py", line 160, in _record
    return method(sql, params)
  File "/home/markmur88/Documentos/Entorno/envAPP/lib/python3.13/site-packages/django/db/backends/utils.py", line 122, in execute
    return super().execute(sql, params)
           ~~~~~~~~~~~~~~~^^^^^^^^^^^^^
  File "/home/markmur88/Documentos/Entorno/envAPP/lib/python3.13/site-packages/django/db/backends/utils.py", line 79, in execute
    return self._execute_with_wrappers(
           ~~~~~~~~~~~~~~~~~~~~~~~~~~~^
        sql, params, many=False, executor=self._execute
        ^^^^^^^^^^^^^^^^^^^^^^^^^^^^^^^^^^^^^^^^^^^^^^^
    )
    ^
  File "/home/markmur88/Documentos/Entorno/envAPP/lib/python3.13/site-packages/django/db/backends/utils.py", line 92, in _execute_with_wrappers
    return executor(sql, params, many, context)
  File "/home/markmur88/Documentos/Entorno/envAPP/lib/python3.13/site-packages/django/db/backends/utils.py", line 100, in _execute
    with self.db.wrap_database_errors:
         ^^^^^^^^^^^^^^^^^^^^^^^^^^^^
  File "/home/markmur88/Documentos/Entorno/envAPP/lib/python3.13/site-packages/django/db/utils.py", line 91, in __exit__
    raise dj_exc_value.with_traceback(traceback) from exc_value
  File "/home/markmur88/Documentos/Entorno/envAPP/lib/python3.13/site-packages/django/db/backends/utils.py", line 105, in _execute
    return self.cursor.execute(sql, params)
           ~~~~~~~~~~~~~~~~~~~^^^^^^^^^^^^^
django.db.utils.ProgrammingError: no existe la relación «auth_user»
LINE 1: ...user"."is_active", "auth_user"."date_joined" FROM "auth_user...
                                                             ^

Internal Server Error: /login/
Not Found: /favicon.ico
Error inesperado durante login: no existe la relación «auth_user»
LINE 1: ...user"."is_active", "auth_user"."date_joined" FROM "auth_user...
                                                             ^
Traceback (most recent call last):
  File "/home/markmur88/Documentos/Entorno/envAPP/lib/python3.13/site-packages/django/db/backends/utils.py", line 105, in _execute
    return self.cursor.execute(sql, params)
           ~~~~~~~~~~~~~~~~~~~^^^^^^^^^^^^^
psycopg2.errors.UndefinedTable: no existe la relación «auth_user»
LINE 1: ...user"."is_active", "auth_user"."date_joined" FROM "auth_user...
                                                             ^


The above exception was the direct cause of the following exception:

Traceback (most recent call last):
  File "/home/markmur88/Documentos/GitHub/api_bank_h2/api/views.py", line 148, in login_view
    user = authenticate(request, username=username, password=password)
  File "/home/markmur88/Documentos/Entorno/envAPP/lib/python3.13/site-packages/django/views/decorators/debug.py", line 75, in sensitive_variables_wrapper
    return func(*func_args, **func_kwargs)
  File "/home/markmur88/Documentos/Entorno/envAPP/lib/python3.13/site-packages/django/contrib/auth/__init__.py", line 114, in authenticate
    user = backend.authenticate(request, **credentials)
  File "/home/markmur88/Documentos/Entorno/envAPP/lib/python3.13/site-packages/django/contrib/auth/backends.py", line 65, in authenticate
    user = UserModel._default_manager.get_by_natural_key(username)
  File "/home/markmur88/Documentos/Entorno/envAPP/lib/python3.13/site-packages/django/contrib/auth/base_user.py", line 37, in get_by_natural_key
    return self.get(**{self.model.USERNAME_FIELD: username})
           ~~~~~~~~^^^^^^^^^^^^^^^^^^^^^^^^^^^^^^^^^^^^^^^^^
  File "/home/markmur88/Documentos/Entorno/envAPP/lib/python3.13/site-packages/django/db/models/manager.py", line 87, in manager_method
    return getattr(self.get_queryset(), name)(*args, **kwargs)
           ~~~~~~~~~~~~~~~~~~~~~~~~~~~~~~~~~~^^^^^^^^^^^^^^^^^
  File "/home/markmur88/Documentos/Entorno/envAPP/lib/python3.13/site-packages/django/db/models/query.py", line 629, in get
    num = len(clone)
  File "/home/markmur88/Documentos/Entorno/envAPP/lib/python3.13/site-packages/django/db/models/query.py", line 366, in __len__
    self._fetch_all()
    ~~~~~~~~~~~~~~~^^
  File "/home/markmur88/Documentos/Entorno/envAPP/lib/python3.13/site-packages/django/db/models/query.py", line 1935, in _fetch_all
    self._result_cache = list(self._iterable_class(self))
                         ~~~~^^^^^^^^^^^^^^^^^^^^^^^^^^^^
  File "/home/markmur88/Documentos/Entorno/envAPP/lib/python3.13/site-packages/django/db/models/query.py", line 91, in __iter__
    results = compiler.execute_sql(
        chunked_fetch=self.chunked_fetch, chunk_size=self.chunk_size
    )
  File "/home/markmur88/Documentos/Entorno/envAPP/lib/python3.13/site-packages/django/db/models/sql/compiler.py", line 1622, in execute_sql
    cursor.execute(sql, params)
    ~~~~~~~~~~~~~~^^^^^^^^^^^^^
  File "/home/markmur88/Documentos/Entorno/envAPP/lib/python3.13/site-packages/debug_toolbar/panels/sql/tracking.py", line 235, in execute
    return self._record(super().execute, sql, params)
           ~~~~~~~~~~~~^^^^^^^^^^^^^^^^^^^^^^^^^^^^^^
  File "/home/markmur88/Documentos/Entorno/envAPP/lib/python3.13/site-packages/debug_toolbar/panels/sql/tracking.py", line 160, in _record
    return method(sql, params)
  File "/home/markmur88/Documentos/Entorno/envAPP/lib/python3.13/site-packages/django/db/backends/utils.py", line 122, in execute
    return super().execute(sql, params)
           ~~~~~~~~~~~~~~~^^^^^^^^^^^^^
  File "/home/markmur88/Documentos/Entorno/envAPP/lib/python3.13/site-packages/django/db/backends/utils.py", line 79, in execute
    return self._execute_with_wrappers(
           ~~~~~~~~~~~~~~~~~~~~~~~~~~~^
        sql, params, many=False, executor=self._execute
        ^^^^^^^^^^^^^^^^^^^^^^^^^^^^^^^^^^^^^^^^^^^^^^^
    )
    ^
  File "/home/markmur88/Documentos/Entorno/envAPP/lib/python3.13/site-packages/django/db/backends/utils.py", line 92, in _execute_with_wrappers
    return executor(sql, params, many, context)
  File "/home/markmur88/Documentos/Entorno/envAPP/lib/python3.13/site-packages/django/db/backends/utils.py", line 100, in _execute
    with self.db.wrap_database_errors:
         ^^^^^^^^^^^^^^^^^^^^^^^^^^^^
  File "/home/markmur88/Documentos/Entorno/envAPP/lib/python3.13/site-packages/django/db/utils.py", line 91, in __exit__
    raise dj_exc_value.with_traceback(traceback) from exc_value
  File "/home/markmur88/Documentos/Entorno/envAPP/lib/python3.13/site-packages/django/db/backends/utils.py", line 105, in _execute
    return self.cursor.execute(sql, params)
           ~~~~~~~~~~~~~~~~~~~^^^^^^^^^^^^^
django.db.utils.ProgrammingError: no existe la relación «auth_user»
LINE 1: ...user"."is_active", "auth_user"."date_joined" FROM "auth_user...
                                                             ^

Internal Server Error: /login/
Error inesperado durante login: no existe la relación «auth_user»
LINE 1: ...user"."is_active", "auth_user"."date_joined" FROM "auth_user...
                                                             ^
Traceback (most recent call last):
  File "/home/markmur88/Documentos/Entorno/envAPP/lib/python3.13/site-packages/django/db/backends/utils.py", line 105, in _execute
    return self.cursor.execute(sql, params)
           ~~~~~~~~~~~~~~~~~~~^^^^^^^^^^^^^
psycopg2.errors.UndefinedTable: no existe la relación «auth_user»
LINE 1: ...user"."is_active", "auth_user"."date_joined" FROM "auth_user...
                                                             ^


The above exception was the direct cause of the following exception:

Traceback (most recent call last):
  File "/home/markmur88/Documentos/GitHub/api_bank_h2/api/views.py", line 148, in login_view
    user = authenticate(request, username=username, password=password)
  File "/home/markmur88/Documentos/Entorno/envAPP/lib/python3.13/site-packages/django/views/decorators/debug.py", line 75, in sensitive_variables_wrapper
    return func(*func_args, **func_kwargs)
  File "/home/markmur88/Documentos/Entorno/envAPP/lib/python3.13/site-packages/django/contrib/auth/__init__.py", line 114, in authenticate
    user = backend.authenticate(request, **credentials)
  File "/home/markmur88/Documentos/Entorno/envAPP/lib/python3.13/site-packages/django/contrib/auth/backends.py", line 65, in authenticate
    user = UserModel._default_manager.get_by_natural_key(username)
  File "/home/markmur88/Documentos/Entorno/envAPP/lib/python3.13/site-packages/django/contrib/auth/base_user.py", line 37, in get_by_natural_key
    return self.get(**{self.model.USERNAME_FIELD: username})
           ~~~~~~~~^^^^^^^^^^^^^^^^^^^^^^^^^^^^^^^^^^^^^^^^^
  File "/home/markmur88/Documentos/Entorno/envAPP/lib/python3.13/site-packages/django/db/models/manager.py", line 87, in manager_method
    return getattr(self.get_queryset(), name)(*args, **kwargs)
           ~~~~~~~~~~~~~~~~~~~~~~~~~~~~~~~~~~^^^^^^^^^^^^^^^^^
  File "/home/markmur88/Documentos/Entorno/envAPP/lib/python3.13/site-packages/django/db/models/query.py", line 629, in get
    num = len(clone)
  File "/home/markmur88/Documentos/Entorno/envAPP/lib/python3.13/site-packages/django/db/models/query.py", line 366, in __len__
    self._fetch_all()
    ~~~~~~~~~~~~~~~^^
  File "/home/markmur88/Documentos/Entorno/envAPP/lib/python3.13/site-packages/django/db/models/query.py", line 1935, in _fetch_all
    self._result_cache = list(self._iterable_class(self))
                         ~~~~^^^^^^^^^^^^^^^^^^^^^^^^^^^^
  File "/home/markmur88/Documentos/Entorno/envAPP/lib/python3.13/site-packages/django/db/models/query.py", line 91, in __iter__
    results = compiler.execute_sql(
        chunked_fetch=self.chunked_fetch, chunk_size=self.chunk_size
    )
  File "/home/markmur88/Documentos/Entorno/envAPP/lib/python3.13/site-packages/django/db/models/sql/compiler.py", line 1622, in execute_sql
    cursor.execute(sql, params)
    ~~~~~~~~~~~~~~^^^^^^^^^^^^^
  File "/home/markmur88/Documentos/Entorno/envAPP/lib/python3.13/site-packages/debug_toolbar/panels/sql/tracking.py", line 235, in execute
    return self._record(super().execute, sql, params)
           ~~~~~~~~~~~~^^^^^^^^^^^^^^^^^^^^^^^^^^^^^^
  File "/home/markmur88/Documentos/Entorno/envAPP/lib/python3.13/site-packages/debug_toolbar/panels/sql/tracking.py", line 160, in _record
    return method(sql, params)
  File "/home/markmur88/Documentos/Entorno/envAPP/lib/python3.13/site-packages/django/db/backends/utils.py", line 122, in execute
    return super().execute(sql, params)
           ~~~~~~~~~~~~~~~^^^^^^^^^^^^^
  File "/home/markmur88/Documentos/Entorno/envAPP/lib/python3.13/site-packages/django/db/backends/utils.py", line 79, in execute
    return self._execute_with_wrappers(
           ~~~~~~~~~~~~~~~~~~~~~~~~~~~^
        sql, params, many=False, executor=self._execute
        ^^^^^^^^^^^^^^^^^^^^^^^^^^^^^^^^^^^^^^^^^^^^^^^
    )
    ^
  File "/home/markmur88/Documentos/Entorno/envAPP/lib/python3.13/site-packages/django/db/backends/utils.py", line 92, in _execute_with_wrappers
    return executor(sql, params, many, context)
  File "/home/markmur88/Documentos/Entorno/envAPP/lib/python3.13/site-packages/django/db/backends/utils.py", line 100, in _execute
    with self.db.wrap_database_errors:
         ^^^^^^^^^^^^^^^^^^^^^^^^^^^^
  File "/home/markmur88/Documentos/Entorno/envAPP/lib/python3.13/site-packages/django/db/utils.py", line 91, in __exit__
    raise dj_exc_value.with_traceback(traceback) from exc_value
  File "/home/markmur88/Documentos/Entorno/envAPP/lib/python3.13/site-packages/django/db/backends/utils.py", line 105, in _execute
    return self.cursor.execute(sql, params)
           ~~~~~~~~~~~~~~~~~~~^^^^^^^^^^^^^
django.db.utils.ProgrammingError: no existe la relación «auth_user»
LINE 1: ...user"."is_active", "auth_user"."date_joined" FROM "auth_user...
                                                             ^

Internal Server Error: /login/
Not Found: /favicon.ico
Error inesperado durante login: no existe la relación «auth_user»
LINE 1: ...user"."is_active", "auth_user"."date_joined" FROM "auth_user...
                                                             ^
Traceback (most recent call last):
  File "/home/markmur88/Documentos/Entorno/envAPP/lib/python3.13/site-packages/django/db/backends/utils.py", line 105, in _execute
    return self.cursor.execute(sql, params)
           ~~~~~~~~~~~~~~~~~~~^^^^^^^^^^^^^
psycopg2.errors.UndefinedTable: no existe la relación «auth_user»
LINE 1: ...user"."is_active", "auth_user"."date_joined" FROM "auth_user...
                                                             ^


The above exception was the direct cause of the following exception:

Traceback (most recent call last):
  File "/home/markmur88/Documentos/GitHub/api_bank_h2/api/views.py", line 148, in login_view
    user = authenticate(request, username=username, password=password)
  File "/home/markmur88/Documentos/Entorno/envAPP/lib/python3.13/site-packages/django/views/decorators/debug.py", line 75, in sensitive_variables_wrapper
    return func(*func_args, **func_kwargs)
  File "/home/markmur88/Documentos/Entorno/envAPP/lib/python3.13/site-packages/django/contrib/auth/__init__.py", line 114, in authenticate
    user = backend.authenticate(request, **credentials)
  File "/home/markmur88/Documentos/Entorno/envAPP/lib/python3.13/site-packages/django/contrib/auth/backends.py", line 65, in authenticate
    user = UserModel._default_manager.get_by_natural_key(username)
  File "/home/markmur88/Documentos/Entorno/envAPP/lib/python3.13/site-packages/django/contrib/auth/base_user.py", line 37, in get_by_natural_key
    return self.get(**{self.model.USERNAME_FIELD: username})
           ~~~~~~~~^^^^^^^^^^^^^^^^^^^^^^^^^^^^^^^^^^^^^^^^^
  File "/home/markmur88/Documentos/Entorno/envAPP/lib/python3.13/site-packages/django/db/models/manager.py", line 87, in manager_method
    return getattr(self.get_queryset(), name)(*args, **kwargs)
           ~~~~~~~~~~~~~~~~~~~~~~~~~~~~~~~~~~^^^^^^^^^^^^^^^^^
  File "/home/markmur88/Documentos/Entorno/envAPP/lib/python3.13/site-packages/django/db/models/query.py", line 629, in get
    num = len(clone)
  File "/home/markmur88/Documentos/Entorno/envAPP/lib/python3.13/site-packages/django/db/models/query.py", line 366, in __len__
    self._fetch_all()
    ~~~~~~~~~~~~~~~^^
  File "/home/markmur88/Documentos/Entorno/envAPP/lib/python3.13/site-packages/django/db/models/query.py", line 1935, in _fetch_all
    self._result_cache = list(self._iterable_class(self))
                         ~~~~^^^^^^^^^^^^^^^^^^^^^^^^^^^^
  File "/home/markmur88/Documentos/Entorno/envAPP/lib/python3.13/site-packages/django/db/models/query.py", line 91, in __iter__
    results = compiler.execute_sql(
        chunked_fetch=self.chunked_fetch, chunk_size=self.chunk_size
    )
  File "/home/markmur88/Documentos/Entorno/envAPP/lib/python3.13/site-packages/django/db/models/sql/compiler.py", line 1622, in execute_sql
    cursor.execute(sql, params)
    ~~~~~~~~~~~~~~^^^^^^^^^^^^^
  File "/home/markmur88/Documentos/Entorno/envAPP/lib/python3.13/site-packages/debug_toolbar/panels/sql/tracking.py", line 235, in execute
    return self._record(super().execute, sql, params)
           ~~~~~~~~~~~~^^^^^^^^^^^^^^^^^^^^^^^^^^^^^^
  File "/home/markmur88/Documentos/Entorno/envAPP/lib/python3.13/site-packages/debug_toolbar/panels/sql/tracking.py", line 160, in _record
    return method(sql, params)
  File "/home/markmur88/Documentos/Entorno/envAPP/lib/python3.13/site-packages/django/db/backends/utils.py", line 122, in execute
    return super().execute(sql, params)
           ~~~~~~~~~~~~~~~^^^^^^^^^^^^^
  File "/home/markmur88/Documentos/Entorno/envAPP/lib/python3.13/site-packages/django/db/backends/utils.py", line 79, in execute
    return self._execute_with_wrappers(
           ~~~~~~~~~~~~~~~~~~~~~~~~~~~^
        sql, params, many=False, executor=self._execute
        ^^^^^^^^^^^^^^^^^^^^^^^^^^^^^^^^^^^^^^^^^^^^^^^
    )
    ^
  File "/home/markmur88/Documentos/Entorno/envAPP/lib/python3.13/site-packages/django/db/backends/utils.py", line 92, in _execute_with_wrappers
    return executor(sql, params, many, context)
  File "/home/markmur88/Documentos/Entorno/envAPP/lib/python3.13/site-packages/django/db/backends/utils.py", line 100, in _execute
    with self.db.wrap_database_errors:
         ^^^^^^^^^^^^^^^^^^^^^^^^^^^^
  File "/home/markmur88/Documentos/Entorno/envAPP/lib/python3.13/site-packages/django/db/utils.py", line 91, in __exit__
    raise dj_exc_value.with_traceback(traceback) from exc_value
  File "/home/markmur88/Documentos/Entorno/envAPP/lib/python3.13/site-packages/django/db/backends/utils.py", line 105, in _execute
    return self.cursor.execute(sql, params)
           ~~~~~~~~~~~~~~~~~~~^^^^^^^^^^^^^
django.db.utils.ProgrammingError: no existe la relación «auth_user»
LINE 1: ...user"."is_active", "auth_user"."date_joined" FROM "auth_user...
                                                             ^

Internal Server Error: /login/

📅 Fecha de ejecución: 2025-05-27 12:30:18
📄 Script: 00_01_sistema.sh
═════════════════════════════════════════════════════════════

📅 Fecha de ejecución: 2025-05-27 12:38:11
📄 Script: 00_03_puertos.sh
═════════════════════════════════════════════════════════════

📅 Fecha de ejecución: 2025-05-27 12:38:12
📄 Script: 00_05_mac.sh
═════════════════════════════════════════════════════════════

📅 Fecha de ejecución: 2025-05-27 12:38:59
📄 Script: 00_06_ufw.sh
═════════════════════════════════════════════════════════════

📅 Fecha de ejecución: 2025-05-27 12:39:15
📄 Script: 00_07_postgres.sh
═════════════════════════════════════════════════════════════

📅 Fecha de ejecución: 2025-05-27 12:39:20
📄 Script: 00_08_migraciones.sh
═════════════════════════════════════════════════════════════

📅 Fecha de ejecución: 2025-05-27 12:40:09
📄 Script: 00_09_cargar_json.sh
═════════════════════════════════════════════════════════════

📅 Fecha de ejecución: 2025-05-27 12:41:29
📄 Script: 00_14_sincronizacion_archivos.sh
═════════════════════════════════════════════════════════════
[1;32m[OK]   VPN (proton0) activa. Conexión segura.[0m
[1;32m[OK]   ✔️ Configuración .env validada.[0m

📅 Fecha de ejecución: 2025-05-27 12:41:31
📄 Script: 00_16_subir_heroku.sh
═════════════════════════════════════════════════════════════

📅 Fecha de ejecución: 2025-05-27 12:43:43
📄 Script: 00_17_sincronizar_bdd.sh
═════════════════════════════════════════════════════════════

📅 Fecha de ejecución: 2025-05-27 21:36:54
📄 Script: 00_07_postgres.sh
═════════════════════════════════════════════════════════════

📅 Fecha de ejecución: 2025-05-27 21:37:03
📄 Script: 00_08_migraciones.sh
═════════════════════════════════════════════════════════════

📅 Fecha de ejecución: 2025-05-27 21:39:56
📄 Script: 00_09_cargar_json.sh
═════════════════════════════════════════════════════════════

📅 Fecha de ejecución: 2025-05-27 21:41:11
📄 Script: 00_14_sincronizacion_archivos.sh
═════════════════════════════════════════════════════════════
[1;32m[OK]   VPN (proton0) activa. Conexión segura.[0m
[1;32m[OK]   ✔️ Configuración .env validada.[0m

📅 Fecha de ejecución: 2025-05-27 21:41:12
📄 Script: 00_16_subir_heroku.sh
═════════════════════════════════════════════════════════════

📅 Fecha de ejecución: 2025-05-27 21:43:54
📄 Script: 00_17_sincronizar_bdd.sh
═════════════════════════════════════════════════════════════

📅 Fecha de ejecución: 2025-05-27 21:47:34
📄 Script: 00_12_pem.sh
═════════════════════════════════════════════════════════════

❌ Error en línea 26: "python3 manage.py genkey"
Abortando ejecución.

📅 Fecha de ejecución: 2025-05-27 21:50:47
📄 Script: 00_07_postgres.sh
═════════════════════════════════════════════════════════════

📅 Fecha de ejecución: 2025-05-27 21:50:50
📄 Script: 00_08_migraciones.sh
═════════════════════════════════════════════════════════════
📅 Fecha de ejecución: 2025-05-27 21:53:31
📄 Script: 00_10_usuario.sh
═════════════════════════════════════════════════════════════

📅 Fecha de ejecución: 2025-05-27 21:53:36
📄 Script: 00_14_sincronizacion_archivos.sh
═════════════════════════════════════════════════════════════
[1;32m[OK]   VPN (proton0) activa. Conexión segura.[0m
[1;32m[OK]   ✔️ Configuración .env validada.[0m

📅 Fecha de ejecución: 2025-05-27 21:53:36
📄 Script: 00_16_subir_heroku.sh
═════════════════════════════════════════════════════════════

📅 Fecha de ejecución: 2025-05-27 21:55:37
📄 Script: 00_17_sincronizar_bdd.sh
═════════════════════════════════════════════════════════════
[1;32m[OK]   VPN (proton0) activa. Conexión segura.[0m
[1;32m[OK]   ✔️ Configuración .env validada.[0m

📅 Fecha de ejecución: 2025-05-27 22:51:13
📄 Script: 00_07_postgres.sh
═════════════════════════════════════════════════════════════

📅 Fecha de ejecución: 2025-05-27 22:51:18
📄 Script: 00_08_migraciones.sh
═════════════════════════════════════════════════════════════
📅 Fecha de ejecución: 2025-05-27 22:51:34
📄 Script: 00_10_usuario.sh
═════════════════════════════════════════════════════════════

📅 Fecha de ejecución: 2025-05-27 22:51:36
📄 Script: 00_12_pem.sh
═════════════════════════════════════════════════════════════

📅 Fecha de ejecución: 2025-05-27 22:51:45
📄 Script: 00_14_sincronizacion_archivos.sh
═════════════════════════════════════════════════════════════
[1;32m[OK]   VPN (proton0) activa. Conexión segura.[0m
[1;31m[ERR]  ❌ ALLOWED_HOSTS contiene '0.0.0.0'. No es seguro para producción.[0m

📅 Fecha de ejecución: 2025-05-27 22:53:34
📄 Script: 00_07_postgres.sh
═════════════════════════════════════════════════════════════

📅 Fecha de ejecución: 2025-05-27 22:53:40
📄 Script: 00_08_migraciones.sh
═════════════════════════════════════════════════════════════
📅 Fecha de ejecución: 2025-05-27 22:54:00
📄 Script: 00_10_usuario.sh
═════════════════════════════════════════════════════════════

📅 Fecha de ejecución: 2025-05-27 22:54:02
📄 Script: 00_12_pem.sh
═════════════════════════════════════════════════════════════

📅 Fecha de ejecución: 2025-05-27 22:54:08
📄 Script: 00_14_sincronizacion_archivos.sh
═════════════════════════════════════════════════════════════
[1;32m[OK]   VPN (proton0) activa. Conexión segura.[0m
[1;31m[ERR]  ❌ ALLOWED_HOSTS contiene '0.0.0.0'. No es seguro para producción.[0m

📅 Fecha de ejecución: 2025-05-27 22:55:58
📄 Script: 00_07_postgres.sh
═════════════════════════════════════════════════════════════

📅 Fecha de ejecución: 2025-05-27 22:56:02
📄 Script: 00_08_migraciones.sh
═════════════════════════════════════════════════════════════
📅 Fecha de ejecución: 2025-05-27 22:56:16
📄 Script: 00_10_usuario.sh
═════════════════════════════════════════════════════════════

📅 Fecha de ejecución: 2025-05-27 22:56:18
📄 Script: 00_12_pem.sh
═════════════════════════════════════════════════════════════

📅 Fecha de ejecución: 2025-05-27 22:56:25
📄 Script: 00_14_sincronizacion_archivos.sh
═════════════════════════════════════════════════════════════
