ERROR 2025-05-07 05:49:49,083 middleware Error en /app/gpt4/transfers/35f7a2b3-a144-438c-aca1-ae3ba4d0681a/send/: No Transfer matches the given query.
Traceback (most recent call last):
  File "/home/markmur88/Documentos/Entorno/venvAPI/lib/python3.13/site-packages/django/shortcuts.py", line 90, in get_object_or_404
    return queryset.get(*args, **kwargs)
           ~~~~~~~~~~~~^^^^^^^^^^^^^^^^^
  File "/home/markmur88/Documentos/Entorno/venvAPI/lib/python3.13/site-packages/django/db/models/query.py", line 633, in get
    raise self.model.DoesNotExist(
        "%s matching query does not exist." % self.model._meta.object_name
    )
api.gpt4.models.Transfer.DoesNotExist: Transfer matching query does not exist.

During handling of the above exception, another exception occurred:

Traceback (most recent call last):
  File "/home/markmur88/Documentos/Entorno/venvAPI/lib/python3.13/site-packages/django/core/handlers/base.py", line 197, in _get_response
    response = wrapped_callback(request, *callback_args, **callback_kwargs)
  File "/home/markmur88/Documentos/GitHub/api_bank_h2/api/gpt4/views.py", line 380, in send_transfer_view
    transfer = get_object_or_404(Transfer, payment_id=payment_id)
  File "/home/markmur88/Documentos/Entorno/venvAPI/lib/python3.13/site-packages/django/shortcuts.py", line 92, in get_object_or_404
    raise Http404(
        "No %s matches the given query." % queryset.model._meta.object_name
    )
django.http.response.Http404: No Transfer matches the given query.
WARNING 2025-05-07 05:49:49,896 log Not Found: /app/gpt4/transfers/35f7a2b3-a144-438c-aca1-ae3ba4d0681a/send/
WARNING 2025-05-07 05:49:50,152 log Not Found: /favicon.ico
ERROR 2025-05-07 05:49:53,485 middleware Error en /app/gpt4/transfers/35f7a2b3-a144-438c-aca1-ae3ba4d0681a/send/: No Transfer matches the given query.
Traceback (most recent call last):
  File "/home/markmur88/Documentos/Entorno/venvAPI/lib/python3.13/site-packages/django/shortcuts.py", line 90, in get_object_or_404
    return queryset.get(*args, **kwargs)
           ~~~~~~~~~~~~^^^^^^^^^^^^^^^^^
  File "/home/markmur88/Documentos/Entorno/venvAPI/lib/python3.13/site-packages/django/db/models/query.py", line 633, in get
    raise self.model.DoesNotExist(
        "%s matching query does not exist." % self.model._meta.object_name
    )
api.gpt4.models.Transfer.DoesNotExist: Transfer matching query does not exist.

During handling of the above exception, another exception occurred:

Traceback (most recent call last):
  File "/home/markmur88/Documentos/Entorno/venvAPI/lib/python3.13/site-packages/django/core/handlers/base.py", line 197, in _get_response
    response = wrapped_callback(request, *callback_args, **callback_kwargs)
  File "/home/markmur88/Documentos/GitHub/api_bank_h2/api/gpt4/views.py", line 380, in send_transfer_view
    transfer = get_object_or_404(Transfer, payment_id=payment_id)
  File "/home/markmur88/Documentos/Entorno/venvAPI/lib/python3.13/site-packages/django/shortcuts.py", line 92, in get_object_or_404
    raise Http404(
        "No %s matches the given query." % queryset.model._meta.object_name
    )
django.http.response.Http404: No Transfer matches the given query.
WARNING 2025-05-07 05:49:53,488 log Not Found: /app/gpt4/transfers/35f7a2b3-a144-438c-aca1-ae3ba4d0681a/send/
ERROR 2025-05-07 05:49:55,842 middleware Error en /app/gpt4/transfers/35f7a2b3-a144-438c-aca1-ae3ba4d0681a/send/: No Transfer matches the given query.
Traceback (most recent call last):
  File "/home/markmur88/Documentos/Entorno/venvAPI/lib/python3.13/site-packages/django/shortcuts.py", line 90, in get_object_or_404
    return queryset.get(*args, **kwargs)
           ~~~~~~~~~~~~^^^^^^^^^^^^^^^^^
  File "/home/markmur88/Documentos/Entorno/venvAPI/lib/python3.13/site-packages/django/db/models/query.py", line 633, in get
    raise self.model.DoesNotExist(
        "%s matching query does not exist." % self.model._meta.object_name
    )
api.gpt4.models.Transfer.DoesNotExist: Transfer matching query does not exist.

During handling of the above exception, another exception occurred:

Traceback (most recent call last):
  File "/home/markmur88/Documentos/Entorno/venvAPI/lib/python3.13/site-packages/django/core/handlers/base.py", line 197, in _get_response
    response = wrapped_callback(request, *callback_args, **callback_kwargs)
  File "/home/markmur88/Documentos/GitHub/api_bank_h2/api/gpt4/views.py", line 380, in send_transfer_view
    transfer = get_object_or_404(Transfer, payment_id=payment_id)
  File "/home/markmur88/Documentos/Entorno/venvAPI/lib/python3.13/site-packages/django/shortcuts.py", line 92, in get_object_or_404
    raise Http404(
        "No %s matches the given query." % queryset.model._meta.object_name
    )
django.http.response.Http404: No Transfer matches the given query.
WARNING 2025-05-07 05:49:55,881 log Not Found: /app/gpt4/transfers/35f7a2b3-a144-438c-aca1-ae3ba4d0681a/send/
